src/test/resources/test_cases/input/101.txt
10000,B,98,25500
10005,S,105,20000
10001,S,100,500
10002,S,100,10000
10003,B,99,50000
10004,S,103,100
10006,B,105,16000
10007,S,98,60000
TSTTSTTST,B,105,999999999
10100,B,105,1
10101,S,96,999985401
10102,S,96,15499
