src/test/resources/test_cases/output/101.txt
trade 10006,10001,100,500
trade 10006,10002,100,10000
trade 10006,10004,103,100
trade 10006,10005,105,5400
trade 10007,10003,99,50000
trade 10007,10000,98,10000
trade TSTTSTTST,10005,105,14600
trade 10101,TSTTSTTST,105,999985399
trade 10101,10100,105,1
trade 10101,10000,98,1
trade 10102,10000,98,15499
